(python3Env) Rachels-MacBook-Pro:flask_mysql rachel$ python server.py
  File "server.py", line 7, in <module>
    mysql = connectToMySQL('mydb')
  File "/Users/rachel/Documents/coding_dojo/python_stack/flask_MySQL/mysqlconnection.py", line 46, in connectToMySQL
    return MySQLConnection(db)
  File "/Users/rachel/Documents/coding_dojo/python_stack/flask_MySQL/mysqlconnection.py", line 12, in __init__
    autocommit = True)
  File "/Users/rachel/Documents/coding_dojo/python_stack/myEnvironments/python3Env/lib/python3.7/site-packages/pymysql/__init__.py", line 94, in Connect
    return Connection(*args, **kwargs)
  File "/Users/rachel/Documents/coding_dojo/python_stack/myEnvironments/python3Env/lib/python3.7/site-packages/pymysql/connections.py", line 327, in __init__
    self.connect()
  File "/Users/rachel/Documents/coding_dojo/python_stack/myEnvironments/python3Env/lib/python3.7/site-packages/pymysql/connections.py", line 598, in connect
    self._request_authentication()
  File "/Users/rachel/Documents/coding_dojo/python_stack/myEnvironments/python3Env/lib/python3.7/site-packages/pymysql/connections.py", line 873, in _request_authentication
    auth_packet = _auth.caching_sha2_password_auth(self, auth_packet)
  File "/Users/rachel/Documents/coding_dojo/python_stack/myEnvironments/python3Env/lib/python3.7/site-packages/pymysql/_auth.py", line 253, in caching_sha2_password_auth
    pkt = _roundtrip(conn, data)
  File "/Users/rachel/Documents/coding_dojo/python_stack/myEnvironments/python3Env/lib/python3.7/site-packages/pymysql/_auth.py", line 112, in _roundtrip
    pkt = conn._read_packet()
  File "/Users/rachel/Documents/coding_dojo/python_stack/myEnvironments/python3Env/lib/python3.7/site-packages/pymysql/connections.py", line 683, in _read_packet
    packet.check_error()
  File "/Users/rachel/Documents/coding_dojo/python_stack/myEnvironments/python3Env/lib/python3.7/site-packages/pymysql/protocol.py", line 220, in check_error
    err.raise_mysql_exception(self._data)
  File "/Users/rachel/Documents/coding_dojo/python_stack/myEnvironments/python3Env/lib/python3.7/site-packages/pymysql/err.py", line 109, in raise_mysql_exception
    raise errorclass(errno, errval)
pymysql.err.OperationalError: (1045, "Access denied for user 'root'@'localhost' (using password: YES)")


Traceback (most recent call last):
  File "server.py", line 7, in <module>
    mysql = connectToMySQL('mydb')
  File "/Users/rachel/Documents/coding_dojo/python_stack/flask_MySQL/mysqlconnection.py", line 46, in connectToMySQL
    return MySQLConnection(db)
  File "/Users/rachel/Documents/coding_dojo/python_stack/flask_MySQL/mysqlconnection.py", line 10, in __init__
    charset = utf8mb4,
NameError: name 'utf8mb4' is not defined

1) 'root'@'localhost' (using password: YES)")
   Supply the correct password to pymysql.connect()
2) NameError: name 'utf8mb4' is not defined
   Solution: charset should be a string


